<?xml version="1.0" encoding="utf-8"?>
<!-- =================================================================================== -->
<!-- |    This document was autogenerated by xacro from schunk_mpz45.xacro             | -->
<!-- |    EDITING THIS FILE BY HAND IS NOT RECOMMENDED                                 | -->
<!-- =================================================================================== -->
<robot name="schunk_mpz45">

  <gazebo>
    <plugin name="gazebo_ros_control" filename="libgazebo_ros_control.so">
      <robotNamespace>/schunk_mpz45</robotNamespace>
    </plugin>
  </gazebo>
  <!-- Conversion were obtained from http://www.e-paint.co.uk/Lab_values.asp
       unless otherwise stated. -->
  <link name="dummy">
  </link>

  <link name="head">
    <inertial>
      <mass value="1"/>
      <origin rpy="1.57079632679 0  -1.57079632679" xyz="0 0 0"/>
      <inertia ixx="0.001" ixy="0" ixz="0" iyy="0.001" iyz="0" izz="0.001"/>
    </inertial>
    <visual>
      <origin rpy="0 0 -1.57079632679" xyz="0 0 0"/>
      <geometry>
        <mesh filename="package://schunk_mpz45/stl/SchunkGripperNoGripperCorrect.stl"/>
      </geometry>
      <material name="">
        <color rgba="0.1882353 0.1960784 0.2039216 1"/>
      </material>
    </visual>
    <collision>
      <origin rpy="0 0 -1.57079632679" xyz="0 0 0"/>
      <geometry>
        <mesh filename="package://schunk_mpz45/stl/SchunkGripperNoGripperCorrect.stl"/>
      </geometry>
      <material name="">
        <color rgba="1 1 0 1"/>
      </material>
    </collision>
  </link>
  <link name="gripper1">
    <inertial>
      <mass value="1"/>
      <origin rpy="1.57079632679 0  -1.57079632679" xyz="0 0 0"/>
      <inertia ixx="0.001" ixy="0" ixz="0" iyy="0.001" iyz="0" izz="0.001"/>
    </inertial>
    <visual>
      <origin rpy="1.57079632679 0  -1.57079632679" xyz="0 0 0"/>
      <geometry>
        <mesh filename="package://schunk_mpz45/stl/SchunkSingleGripper3.stl"/>
      </geometry>
      <material name="">
        <color rgba="0.9254902 0.9254902 0.9058824 1"/>
      </material>
    </visual>
    <collision>
      <origin rpy="1.57079632679 0  -1.57079632679" xyz="0 0 0"/>
      <geometry>
        <mesh filename="package://schunk_mpz45/stl/SchunkSingleGripper3.stl"/>
      </geometry>
      <material name="">
        <color rgba="1 1 0 1"/>
      </material>
    </collision>
  </link>
  <link name="gripper2">
    <inertial>
      <mass value="1"/>
      <origin rpy="1.57079632679 0  -1.57079632679" xyz="0 0 0"/>
      <inertia ixx="0.001" ixy="0" ixz="0" iyy="0.001" iyz="0" izz="0.001"/>
    </inertial>
    <visual>
      <origin rpy="1.57079632679 0  -1.57079632679" xyz="0 0 0"/>
      <geometry>
        <mesh filename="package://schunk_mpz45/stl/SchunkSingleGripper3.stl"/>
      </geometry>
      <material name="">
        <color rgba="0.9254902 0.9254902 0.9058824 1"/>
      </material>
    </visual>
    <collision>
      <origin rpy="1.57079632679 0  -1.57079632679" xyz="0 0 0"/>
      <geometry>
        <mesh filename="package://schunk_mpz45/stl/SchunkSingleGripper3.stl"/>
      </geometry>
      <material name="">
        <color rgba="1 1 0 1"/>
      </material>
    </collision>
  </link>
  <link name="gripper3">
    <inertial>
      <mass value="1"/>
      <origin rpy="1.57079632679 0  -1.57079632679" xyz="0 0 0"/>
      <inertia ixx="0.001" ixy="0" ixz="0" iyy="0.001" iyz="0" izz="0.001"/>
    </inertial>
    <visual>
      <origin rpy="1.57079632679 0  -1.57079632679" xyz="0 0 0"/>
      <geometry>
        <mesh filename="package://schunk_mpz45/stl/SchunkSingleGripper3.stl"/>
      </geometry>
      <material name="">
        <color rgba="0.9254902 0.9254902 0.9058824 1"/>
      </material>
    </visual>
    <collision>
      <origin rpy="1.57079632679 0  -1.57079632679" xyz="0 0 0"/>
      <geometry>
        <mesh filename="package://schunk_mpz45/stl/SchunkSingleGripper3.stl"/>
      </geometry>
      <material name="">
        <color rgba="1 1 0 1"/>
      </material>
    </collision>
  </link>
  <link name="eef">
    <visual>
      <origin rpy="0 0 0" xyz="0 0 0"/>
      <geometry>
        <sphere radius="0.001"/>
      </geometry>
      <material name="Cyan">
        <color rgba="0 1.0 1.0 1.0"/>
      </material>
    </visual>
  </link>
  <joint name="dummy" type="fixed">
    <parent link="dummy"/>
    <child link="head"/>
  </joint>
  <joint name="joint_7" type="prismatic">
    <origin rpy="-1.57079632679 -2.61799387799 -1.57079632679" xyz="0 0 0"/>
    <parent link="head"/>
    <child link="gripper1"/>
    <limit effort="310" lower="0" upper="0.005" velocity="0.1"/>
  </joint>
  <joint name="joint_8" type="prismatic">
    <origin rpy="-1.57079632679 -0.523598775598 -1.57079632679" xyz="0 0 0"/>
    <parent link="head"/>
    <child link="gripper2"/>
    <limit effort="310" lower="0" upper="0.005" velocity="0.1"/>
    <mimic joint="joint_7"/>
  </joint>
  <joint name="joint_9" type="prismatic">
    <origin rpy="0 1.57079632679 0" xyz="0 0 0"/>
    <parent link="head"/>
    <child link="gripper3"/>
    <limit effort="310" lower="0" upper="0.005" velocity="0.1"/>
    <mimic joint="joint_7"/>
  </joint>
  <joint name="eef-head" type="fixed">
    <origin rpy="0 0 0" xyz="0.05 0 0"/>
    <parent link="head"/>
    <child link="eef"/>
  </joint>
  <!-- transmission list -->
  <transmission name="tran7">
    <type>transmission_interface/SimpleTransmission</type>
    <joint name="joint_7">
      <hardwareInterface>hardware_interface/EffortJointInterface</hardwareInterface>
    </joint>
    <actuator name="motor7">
      <hardwareInterface>hardware_interface/EffortJointInterface</hardwareInterface>
      <mechanicalReduction>1</mechanicalReduction>
    </actuator>
  </transmission>
  <transmission name="tran8">
    <type>transmission_interface/SimpleTransmission</type>
    <joint name="joint_8">
      <hardwareInterface>hardware_interface/EffortJointInterface</hardwareInterface>
    </joint>
    <actuator name="motor8">
      <hardwareInterface>hardware_interface/EffortJointInterface</hardwareInterface>
      <mechanicalReduction>1</mechanicalReduction>
    </actuator>
  </transmission>
  <transmission name="tran9">
    <type>transmission_interface/SimpleTransmission</type>
    <joint name="joint_9">
      <hardwareInterface>hardware_interface/EffortJointInterface</hardwareInterface>
    </joint>
    <actuator name="motor9">
      <hardwareInterface>hardware_interface/EffortJointInterface</hardwareInterface>
      <mechanicalReduction>1</mechanicalReduction>
    </actuator>
  </transmission>
  <!-- end of transmission list -->
  <!-- Gazebo-specific link properties -->
  <gazebo reference="head">
    <material>Gazebo/Grey</material>
    <turnGravityOff>true</turnGravityOff>
  </gazebo>
  <gazebo reference="gripper1">
    <material>Gazebo/White</material>
    <turnGravityOff>true</turnGravityOff>
  </gazebo>
  <gazebo reference="gripper2">
    <material>Gazebo/White</material>
    <turnGravityOff>true</turnGravityOff>
  </gazebo>
  <gazebo reference="gripper3">
    <material>Gazebo/White</material>
    <turnGravityOff>true</turnGravityOff>
  </gazebo>
  <!-- ros_control plugin -->
</robot>

