<?xml version="1.0" ?>
<robot xmlns:xacro="http://ros.org/wiki/xacro">
    <xacro:include filename="$(find abb_resources)/urdf/common_materials.xacro" />
    <xacro:macro name="schunk_mpz45" params="prefix">
        <link name="${prefix}head">
            <inertial>
                <mass value="1" />
                <origin rpy="0 0 ${-1 / 2 * pi}" xyz="0 0 0" />
                <inertia ixx="0.001" ixy="0" ixz="0" iyy="0.001" iyz="0" izz="0.001" />
            </inertial>
            <visual>
                <origin rpy="0 0 ${-1 / 2 * pi}" xyz="0 0 0" />
                <geometry>
                    <mesh filename="package://schunk_mpz45/stl/SchunkGripperNoGripperCorrect.stl" />
                </geometry>
                <xacro:material_abb_black />
            </visual>
            <collision>
                <origin rpy="0 0 ${-1 / 2 * pi}" xyz="0 0 0" />
                <geometry>
                    <mesh filename="package://schunk_mpz45/stl/SchunkGripperNoGripperCorrect.stl" />
                </geometry>
                <material name="">
                    <color rgba="1 1 0 1" />
                </material>
            </collision>
        </link>
        <link name="${prefix}gripper1">
            <inertial>
                <mass value="1" />
                <origin rpy="${1 / 2 * pi} 0  ${-1 / 2 * pi}" xyz="0 0 0" />
                <inertia ixx="0.001" ixy="0" ixz="0" iyy="0.001" iyz="0" izz="0.001" />
            </inertial>
            <visual>
                <origin rpy="${1 / 2 * pi} 0  ${-1 / 2 * pi}" xyz="0 0 0" />
                <geometry>
                    <mesh filename="package://schunk_mpz45/stl/SchunkSingleGripper3.stl" />
                </geometry>
                <xacro:material_abb_white />
            </visual>
            <collision>
                <origin rpy="${1 / 2 * pi} 0  ${-1 / 2 * pi}" xyz="0 0 0" />
                <geometry>
                    <mesh filename="package://schunk_mpz45/stl/SchunkSingleGripper3.stl" />
                </geometry>
                <material name="">
                    <color rgba="1 1 0 1" />
                </material>
            </collision>
        </link>
        <link name="${prefix}gripper2">
            <inertial>
                <mass value="1" />
                <origin rpy="${1 / 2 * pi} 0  ${-1 / 2 * pi}" xyz="0 0 0" />
                <inertia ixx="0.001" ixy="0" ixz="0" iyy="0.001" iyz="0" izz="0.001" />
            </inertial>
            <visual>
                <origin rpy="${1 / 2 * pi} 0  ${-1 / 2 * pi}" xyz="0 0 0" />
                <geometry>
                    <mesh filename="package://schunk_mpz45/stl/SchunkSingleGripper3.stl" />
                </geometry>
                <xacro:material_abb_white />
            </visual>
            <collision>
                <origin rpy="${1 / 2 * pi} 0  ${-1 / 2 * pi}" xyz="0 0 0" />
                <geometry>
                    <mesh filename="package://schunk_mpz45/stl/SchunkSingleGripper3.stl" />
                </geometry>
                <material name="">
                    <color rgba="1 1 0 1" />
                </material>
            </collision>
        </link>
        <link name="${prefix}gripper3">
            <inertial>
                <mass value="1" />
                <origin rpy="${1 / 2 * pi} 0  ${-1 / 2 * pi}" xyz="0 0 0" />
                <inertia ixx="0.001" ixy="0" ixz="0" iyy="0.001" iyz="0" izz="0.001" />
            </inertial>
            <visual>
                <origin rpy="${1 / 2 * pi} 0  ${-1 / 2 * pi}" xyz="0 0 0" />
                <geometry>
                    <mesh filename="package://schunk_mpz45/stl/SchunkSingleGripper3.stl" />
                </geometry>
                <xacro:material_abb_white />
            </visual>
            <collision>
                <origin rpy="${1 / 2 * pi} 0  ${-1 / 2 * pi}" xyz="0 0 0" />
                <geometry>
                    <mesh filename="package://schunk_mpz45/stl/SchunkSingleGripper3.stl" />
                </geometry>
                <material name="">
                    <color rgba="1 1 0 1" />
                </material>
            </collision>
        </link>
        <link name="${prefix}eef">
            <visual>
                <origin xyz="0 0 0" rpy="0 0 0" />
                <geometry>
                    <sphere radius="0.001"/>
                </geometry>
                <material name="Cyan">
                  <color rgba="0 1.0 1.0 1.0"/>
                </material>
              </visual>
        </link>
        <joint name="${prefix}joint_7" type="prismatic">
            <origin rpy="${-1 / 2 * pi} ${-5 / 6 * pi} ${-1 / 2 * pi}" xyz="0 0 0" />
            <parent link="${prefix}head" />
            <child link="${prefix}gripper1" />
            <limit effort="310" lower="0" upper="0.005" velocity="0.1"/>
        </joint>
        <joint name="${prefix}joint_8" type="prismatic">
            <origin rpy="${-1 / 2 * pi} ${-1 / 6 * pi} ${-1 / 2 * pi}" xyz="0 0 0" />
            <parent link="${prefix}head" />
            <child link="${prefix}gripper2" />
            <limit effort="310" lower="0" upper="0.005" velocity="0.1" />
            <mimic joint="${prefix}joint_7"/> 
        </joint>
        <joint name="${prefix}joint_9" type="prismatic">
            <origin rpy="0 ${1 / 2 * pi} 0" xyz="0 0 0" />
            <parent link="${prefix}head" />
            <child link="${prefix}gripper3" />
            <limit effort="310" lower="0" upper="0.005" velocity="0.1" />
            <mimic joint="${prefix}joint_7"/> 
        </joint>
        <joint name="${prefix}eef-head" type="fixed">
            <origin rpy="0 0 0" xyz="0.05 0 0" />
            <parent link="${prefix}head" />
            <child link="${prefix}eef" />
        </joint>
    </xacro:macro>
</robot>

<!-- Schunk specifications according to:  https://schunk.com/fileadmin/pim/docs/IM0020092.PDF-->